Workbook

Sheet Main Level
A1: RODRIGUEZ RESIDENCE - MAIN LEVEL LUMBER TAKEOFF
A3: Description | B3: Size | C3: Qty | D3: Unit | E3: Total LF/EA | F3: Notes
A4: EXTERIOR WALLS - 2x6 @ 16" O.C. (LSL for walls >12')
A5: LSL studs - Living Room (26' walls) | B5: 1⅝x14 LSL-26 | C5: 60 | D5: EA | E5: =C5*26 -> 1560 | F5: 1⅝x14 LSL @ 5" O.C. per S1 (~25 LF)
A6: LSL studs - Entry (20' walls) | B6: 1⅝x6 LSL-20 | C6: 24 | D6: EA | E6: =C6*20 -> 480 | F6: 1⅝x6 LSL @ 16" O.C.
A7: Exterior studs - Standard (10' walls) | B7: 2x6x10 #2 | C7: 280 | D7: EA | E7: =C7*10 -> 2800 | F7: ~350 LF perimeter @ 16" O.C.
A8: Exterior studs - Garage (12' walls) | B8: 2x6x12 #2 | C8: 96 | D8: EA | E8: =C8*12 -> 1152 | F8: ~128 LF garage perimeter
A9: Bottom plates - Exterior | B9: 2x6x16 #2 | C9: 28 | D9: EA | E9: =C9*16 -> 448 | F9: ~440 LF total ext walls
A10: Double top plates - Exterior | B10: 2x6x16 #2 | C10: 56 | D10: EA | E10: =C10*16 -> 896 | F10: 2 rows x 28 pcs
A11: Subtotal Exterior Wall LF: | E11: =SUM(E5:E10) -> 7336
A13: INTERIOR WALLS - 2x4 #2 @ 16" O.C.
A14: Interior studs - 10' walls | B14: 2x4x10 #2 | C14: 225 | D14: EA | E14: =C14*10 -> 2250 | F14: ~300 LF int walls @ 16" O.C.
A15: Interior studs - 12' walls (Garage area) | B15: 2x4x12 #2 | C15: 36 | D15: EA | E15: =C15*12 -> 432 | F15: Per S2 garage 12' ceiling
A16: Bottom plates - Interior | B16: 2x4x16 #2 | C16: 20 | D16: EA | E16: =C16*16 -> 320 | F16: ~320 LF total int walls
A17: Double top plates - Interior | B17: 2x4x16 #2 | C17: 40 | D17: EA | E17: =C17*16 -> 640 | F17: 2 rows x 20 pcs
A18: Subtotal Interior Wall LF: | E18: =SUM(E14:E17) -> 3642
A20: SPECIAL FRAMING - 8" PSL Walls per S2
A21: PSL studs - 8" walls @ 16" O.C. | B21: 1⅝x7½ PSL-10 | C21: 24 | D21: EA | E21: =C21*10 -> 240 | F21: Per wall framing table 8" walls
A22: Subtotal Special Framing LF: | E22: =SUM(E21:E21) -> 240
A24: HEADERS #2 - Per Door/Window Schedule A104
A25: Double 2x6 headers - 3'-2" openings | B25: 2x6x4 #2 | C25: 40 | D25: EA | E25: =C25*4 -> 160 | F25: 10 ext doors x 2 + 10 int
A26: Double 2x6 headers - 6'-3" openings | B26: 2x6x8 #2 | C26: 14 | D26: EA | E26: =C26*8 -> 112 | F26: 5 pocket + 1 closet + 1 iron
A27: LVL headers - Garage (20' spans) | B27: 3½x14 LVL | C27: 8 | D27: EA | E27: =C27*20 -> 160 | F27: 4 garage doors x 2 ply
A28: LVL headers - Windows | B28: 3½x9½ LVL | C28: 32 | D28: EA | E28: =C28*8 -> 256 | F28: Avg 8' window headers
A29: Subtotal Headers LF: | E29: =SUM(E25:E28) -> 688
A31: ENGINEERED BEAMS - Per S2 Floor Framing
A32: (3) 3½x14 LVL beam - Living/Kitchen | B32: 3½x14 LVL | C32: 6 | D32: EA | E32: =C32*24 -> 144 | F32: ~24' spans typ
A33: (4) 3½x14 LVL beam - Entry spans | B33: 3½x14 LVL | C33: 8 | D33: EA | E33: =C33*20 -> 160 | F33: ~20' spans
A34: (2) 3½x11⅞ LVL beam - Secondary | B34: 3½x11⅞ LVL | C34: 8 | D34: EA | E34: =C34*16 -> 128 | F34: ~16' spans
A35: (3) 3½x9½ LVL beam - Short spans | B35: 3½x9½ LVL | C35: 6 | D35: EA | E35: =C35*12 -> 72 | F35: ~12' spans
A36: 1¼x11⅞ Rim board | B36: 1¼x11⅞ LVL | C36: 28 | D36: EA | E36: =C36*16 -> 448 | F36: ~440 LF perimeter
A37: Subtotal Beams LF: | E37: =SUM(E32:E36) -> 952
A39: WALL SHEATHING - 1" OX Board
A40: 1" OX Board sheathing | B40: 4x8 | C40: 180 | D40: SHT | E40: =C40*32 -> 5760 | F40: ~5,760 SF ext walls
A41: 1" OX Board sheathing (shearwalls) | B41: 4x8 | C41: 45 | D41: SHT | E41: =C41*32 -> 1440 | F41: ~1,440 SF shearwalls
A42: Subtotal Sheathing SF: | E42: =SUM(E40:E41) -> 7200
A44: BLOCKING & MISCELLANEOUS #2
A45: Fire blocking - 2x4 | B45: 2x4x16 #2 | C45: 40 | D45: EA | E45: =C45*16 -> 640 | F45: At floor/ceiling lines
A46: Fire blocking - 2x6 | B46: 2x6x16 #2 | C46: 30 | D46: EA | E46: =C46*16 -> 480 | F46: At floor/ceiling lines
A47: Shear blocking - 2x | B47: 2x4x16 #2 | C47: 25 | D47: EA | E47: =C47*16 -> 400 | F47: Per DA callouts on S4/S5
...

Sheet Summary
A1: RODRIGUEZ RESIDENCE - LUMBER TAKEOFF SUMMARY
A2: Oak Valley Estates Lot 5, Kanarraville, Utah
A3: Total SF: 6,993 (Main ~4,400 + Upper ~1,500 + Basement ~1,100)
A5: Category | B5: Main Level | C5: Upper Level | D5: Basement | E5: ADU | F5: TOTAL
A6: 2x6 Studs (LF) | B6: ='Main Level'!E6 -> 480 | C6: ='Upper Level'!E6 -> 192 | D6: 0 | E6: =ADU!E6 -> 128 | F6: =SUM(B6:E6) -> 800
A7: 2x4 Studs (LF) | B7: ='Main Level'!E14 -> 2250 | C7: ='Upper Level'!E13 -> 256 | D7: ='Basement Level'!E6 -> 80 | E7: =ADU!E13 -> 128 | F7: =SUM(B7:E7) -> 2714
A8: Plates (LF) | B8: ='Main Level'!E9 -> 448 | C8: ='Upper Level'!E9 -> 0 | D8: ='Basement Level'!E8 -> 690 | E8: =ADU!E9 -> 0 | F8: =SUM(B8:E8) -> 1138
A9: Headers (LF) | B9: ='Main Level'!E27 -> 160 | C9: ='Upper Level'!E22 -> 1760 | D9: ='Basement Level'!E14 -> 0 | E9: =ADU!E22 -> 1216 | F9: =SUM(B9:E9) -> 3136
A10: LVL Beams (LF) | B10: ='Main Level'!E35 -> 72 | C10: 0 | D10: 0 | E10: 0 | F10: =SUM(B10:E10) -> 72
A11: Wall Sheathing (SF) | B11: ='Main Level'!E41 -> 1440 | C11: ='Upper Level'!E27 -> 192 | D11: 0 | E11: =ADU!E27 -> 160 | F11: =SUM(B11:E11) -> 1792
A12: Floor Deck (SF) | B12: ='Main Level'!E48 -> 600 | C12: ='Upper Level'!E35 -> 0 | D12: 0 | E12: 0 | F12: =SUM(B12:E12) -> 600
A13: Roof Deck (SF) | B13: ='Main Level'!E55 -> 0 | C13: 0 | D13: 0 | E13: 0 | F13: =SUM(B13:E13) -> 0
A15: NOTES:
A16: 1. Trusses (floor and roof) excluded - by truss supplier
A17: 2. Steel beams/columns on separate tab - by steel contractor
A18: 3. Add 10-15% waste factor when ordering
A19: 4. Verify all quantities against final approved plans before ordering
A20: 5. Per structural plans S1-S8 by Rosenberg Engineering, Job# 14040-25

Sheet Upper Level
A1: RODRIGUEZ RESIDENCE - UPPER LEVEL LUMBER TAKEOFF
A3: Description | B3: Size | C3: Qty | D3: Unit | E3: Total LF/EA | F3: Notes
A4: EXTERIOR WALLS - 2x6 #2 @ 16" O.C.
A5: Exterior studs - 10' walls | B5: 2x6x10 #2 | C5: 130 | D5: EA | E5: =C5*10 -> 1300 | F5: ~175 LF perimeter @ 16" O.C.
A6: Bottom plates - Exterior | B6: 2x6x16 #2 | C6: 12 | D6: EA | E6: =C6*16 -> 192 | F6: ~175 LF total
A7: Double top plates - Exterior | B7: 2x6x16 #2 | C7: 24 | D7: EA | E7: =C7*16 -> 384 | F7: 2 rows x 12 pcs
A8: Subtotal Exterior Wall LF: | E8: =SUM(E5:E7) -> 1876
A10: INTERIOR WALLS - 2x4 #2 @ 16" O.C.
A11: Interior studs - 10' walls | B11: 2x4x10 #2 | C11: 75 | D11: EA | E11: =C11*10 -> 750 | F11: ~100 LF int walls @ 16" O.C.
A12: Bottom plates - Interior | B12: 2x4x16 #2 | C12: 8 | D12: EA | E12: =C12*16 -> 128 | F12: ~100 LF total
A13: Double top plates - Interior | B13: 2x4x16 #2 | C13: 16 | D13: EA | E13: =C13*16 -> 256 | F13: 2 rows x 8 pcs
A14: Subtotal Interior Wall LF: | E14: =SUM(E11:E13) -> 1134
A16: HEADERS #2 - Per Door Schedule A104
A17: Double 2x6 headers - 2'-8" openings | B17: 2x6x4 #2 | C17: 12 | D17: EA | E17: =C17*4 -> 48 | F17: 3 TMF doors + 3 pocket
A18: Double 2x6 headers - 3'-2" openings | B18: 2x6x4 #2 | C18: 6 | D18: EA | E18: =C18*4 -> 24 | F18: 1 ext + 2 misc
A19: Subtotal Headers LF: | E19: =SUM(E17:E18) -> 72
A21: WALL SHEATHING - 1" OX Board
A22: 1" OX Board sheathing | B22: 4x8 | C22: 55 | D22: SHT | E22: =C22*32 -> 1760 | F22: ~1,750 SF ext walls
A23: Subtotal Sheathing SF: | E23: =SUM(E22:E22) -> 1760
A25: BLOCKING & MISCELLANEOUS #2
A26: Fire blocking - 2x4 | B26: 2x4x16 #2 | C26: 10 | D26: EA | E26: =C26*16 -> 160 | F26: At ceiling lines
A27: Fire blocking - 2x6 | B27: 2x6x16 #2 | C27: 12 | D27: EA | E27: =C27*16 -> 192 | F27: At ceiling lines
A28: Cripples and trimmers | B28: 2x6x10 #2 | C28: 20 | D28: EA | E28: =C28*10 -> 200 | F28: At openings
A29: Backing - 2x6 | B29: 2x6x16 #2 | C29: 8 | D29: EA | E29: =C29*16 -> 128 | F29: Fixtures
A30: Subtotal Blocking LF: | E30: =SUM(E26:E29) -> 680
A32: FLOOR DECK SHEATHING - 1.125 Advantec
A33: 1.125" Advantec T&G floor deck | B33: 4x8 | C33: 48 | D33: SHT | E33: =C33*32 -> 1536 | F33: ~1,536 SF upper floor
A34: Subtotal Floor Deck SF: | E34: =SUM(E33:E33) -> 1536

Sheet Basement Level
A1: RODRIGUEZ RESIDENCE - BASEMENT LEVEL LUMBER TAKEOFF
A3: Description | B3: Size | C3: Qty | D3: Unit | E3: Total LF/EA | F3: Notes
A4: INTERIOR PARTITIONS - 2x4 #2 @ 16" O.C. (Concrete ext walls)
A5: Interior studs - 10' walls | B5: 2x4x10 #2 | C5: 45 | D5: EA | E5: =C5*10 -> 450 | F5: ~60 LF int partitions
A6: Bottom plates (PT for slab contact) | B6: 2x4x16 PT | C6: 5 | D6: EA | E6: =C6*16 -> 80 | F6: ~60 LF total
A7: Top plates - Interior | B7: 2x4x16 #2 | C7: 10 | D7: EA | E7: =C7*16 -> 160 | F7: 2 rows x 5 pcs
A8: Subtotal Interior Wall LF: | E8: =SUM(E5:E7) -> 690
A10: HEADERS #2
A11: Double 2x4 headers - 2'-8" openings | B11: 2x4x4 #2 | C11: 6 | D11: EA | E11: =C11*4 -> 24 | F11: 3 TMF doors
A12: Vault door frame - steel | B12: --- | C12: 1 | D12: EA | E12: 1 | F12: By vault door supplier
A13: Subtotal Headers LF: | E13: =SUM(E11:E12) -> 25
A15: BLOCKING & MISCELLANEOUS #2
A16: Blocking - 2x4 | B16: 2x4x16 #2 | C16: 6 | D16: EA | E16: =C16*16 -> 96 | F16: At ceiling/wall intersections
A17: Furring strips for finishes | B17: 1x3x16 #2 | C17: 20 | D17: EA | E17: =C17*16 -> 320 | F17: Against concrete walls
A18: Subtotal Blocking LF: | E18: =SUM(E16:E17) -> 416

Sheet ADU
A1: RODRIGUEZ RESIDENCE - ADU LUMBER TAKEOFF
A3: Description | B3: Size | C3: Qty | D3: Unit | E3: Total LF/EA | F3: Notes
A4: EXTERIOR WALLS - 2x6 #2 @ 16" O.C.
A5: Exterior studs - 10' walls | B5: 2x6x10 #2 | C5: 90 | D5: EA | E5: =C5*10 -> 900 | F5: ~120 LF perimeter @ 16" O.C.
A6: Bottom plates - Exterior | B6: 2x6x16 #2 | C6: 8 | D6: EA | E6: =C6*16 -> 128 | F6: ~120 LF total
A7: Double top plates - Exterior | B7: 2x6x16 #2 | C7: 16 | D7: EA | E7: =C7*16 -> 256 | F7: 2 rows x 8 pcs
A8: Subtotal Exterior Wall LF: | E8: =SUM(E5:E7) -> 1284
A10: INTERIOR WALLS - 2x4 #2 @ 16" O.C.
A11: Interior studs - 10' walls | B11: 2x4x10 #2 | C11: 36 | D11: EA | E11: =C11*10 -> 360 | F11: ~48 LF int walls
A12: Bottom plates - Interior | B12: 2x4x16 #2 | C12: 4 | D12: EA | E12: =C12*16 -> 64 | F12: ~48 LF total
A13: Double top plates - Interior | B13: 2x4x16 #2 | C13: 8 | D13: EA | E13: =C13*16 -> 128 | F13: 2 rows
A14: Subtotal Interior Wall LF: | E14: =SUM(E11:E13) -> 552
A16: HEADERS #2
A17: Double 2x6 headers - door openings | B17: 2x6x4 #2 | C17: 8 | D17: EA | E17: =C17*4 -> 32 | F17: 4 doors
A18: Double 2x6 headers - windows | B18: 2x6x8 #2 | C18: 8 | D18: EA | E18: =C18*8 -> 64 | F18: 4 windows
A19: Subtotal Headers LF: | E19: =SUM(E17:E18) -> 96
A21: WALL SHEATHING - 1" OX Board
A22: 1" OX Board sheathing | B22: 4x8 | C22: 38 | D22: SHT | E22: =C22*32 -> 1216 | F22: ~1,200 SF ext walls
A23: Subtotal Sheathing SF: | E23: =SUM(E22:E22) -> 1216
A25: BLOCKING & MISCELLANEOUS #2
A26: Fire blocking - 2x6 | B26: 2x6x16 #2 | C26: 8 | D26: EA | E26: =C26*16 -> 128 | F26: At ceiling lines
A27: Cripples and trimmers | B27: 2x6x10 #2 | C27: 16 | D27: EA | E27: =C27*10 -> 160 | F27: At openings
A28: Subtotal Blocking LF: | E28: =SUM(E26:E27) -> 288

Sheet Hardware
A1: RODRIGUEZ RESIDENCE - HARDWARE TAKEOFF
A3: Description | B3: Size | C3: Qty | D3: Unit | E3: Total LF/EA | F3: Notes
A4: SIMPSON STRONG-TIE - Per Shearwall Plans S4/S5/S6
A5: STB16 Tie-down (main shearwalls) | B5: STB16 | C5: 24 | D5: EA | E5: =C5 -> 24 | F5: Triangle symbols on S4/S5
A6: HTT6 Tie-down (heavy shearwalls) | B6: HTT6 | C6: 16 | D6: EA | E6: =C6 -> 16 | F6: Per S4 legend
A7: STHD14 Tie-down (special frames) | B7: STHD14 | C7: 8 | D7: EA | E7: =C7 -> 8 | F7: Filled triangle symbols
A8: MSTC50 Strap tie | B8: MSTC50 | C8: 20 | D8: EA | E8: =C8 -> 20 | F8: Circle symbols on S4/S5
A9: MSTB6 Straps | B9: MSTB6 | C9: 12 | D9: EA | E9: =C9 -> 12 | F9: Filled circles
A10: H2.5A Hurricane ties | B10: H2.5A | C10: 200 | D10: EA | E10: =C10 -> 200 | F10: At every roof truss
A11: A35 Framing angles | B11: A35 | C11: 150 | D11: EA | E11: =C11 -> 150 | F11: Beam/column connections
A12: LUS28 Joist hangers | B12: LUS28 | C12: 80 | D12: EA | E12: =C12 -> 80 | F12: Floor connections
A13: HU210 Heavy hangers (LVL) | B13: HU210 | C13: 40 | D13: EA | E13: =C13 -> 40 | F13: LVL beam connections
A14: CB44 Post caps | B14: CB44 | C14: 24 | D14: EA | E14: =C14 -> 24 | F14: Beam to post connections
A15: Total Simpson Hardware EA: | E15: =SUM(E5:E14) -> 574
A17: ANCHOR BOLTS - Per Foundation Plan S6
A18: ½" x 10" Anchor bolts @ 6' O.C. | B18: ½x10 AB | C18: 75 | D18: EA | E18: =C18 -> 75 | F18: Standard sill anchor
A19: ½" x 10" Anchor bolts @ 24" O.C. (shearwalls) | B19: ½x10 AB | C19: 40 | D19: EA | E19: =C19 -> 40 | F19: SW2 per schedule
A20: 5/8" x 10" Anchor bolts (heavy shearwalls) | B20: 5/8x10 AB | C20: 24 | D20: EA | E20: =C20 -> 24 | F20: SW3/SW4 per schedule
A21: Simpson TITEN HD ¾" (per panel) | B21: TITEN HD | C21: 16 | D21: EA | E21: =C21 -> 16 | F21: SW4 both sides
A22: Total Anchor Bolts EA: | E22: =SUM(E18:E21) -> 155
A24: FASTENERS - Per S8 General Notes
A25: 16d sinker nails (framing) | B25: 16d | C25: 100 | D25: LB | E25: =C25 -> 100 | F25: General framing
A26: 10d common nails (sheathing) | B26: 10d | C26: 75 | D26: LB | E26: =C26 -> 75 | F26: Roof deck
A27: 8d common nails (sheathing 6" O.C.) | B27: 8d | C27: 100 | D27: LB | E27: =C27 -> 100 | F27: Wall sheathing
A28: 3" deck screws | B28: #10x3 | C28: 50 | D28: LB | E28: =C28 -> 50 | F28: Advantec floor deck
A29: Simpson Strong-Drive SD screws | B29: SD9112 | C29: 25 | D29: LB | E29: =C29 -> 25 | F29: Hardware attachment
A30: Total Fasteners LB: | E30: =SUM(E25:E29) -> 350
A32: SHEARWALL SPECIFIC - Per Schedule S4/S5
A33: Simpson DSC drag strut connectors | B33: DSC | C33: 32 | D33: EA | E33: =C33 -> 32 | F33: DA callouts on plan
A34: Simpson CS16 continuous strap | B34: CS16 | C34: 8 | D34: EA | E34: =C34 -> 8 | F34: Multi-story shearwalls
A35: Portal frame anchors (garage) | B35: PF | C35: 8 | D35: EA | E35: =C35 -> 8 | F35: SW-P per S5
A36: Total Shearwall Hardware EA: | E36: =SUM(E33:E35) -> 48

Sheet Steel (Separate)
A1: RODRIGUEZ RESIDENCE - STEEL BEAMS (BY STEEL CONTRACTOR)
A3: Description | B3: Size | C3: Qty | D3: Unit | E3: Total LF/EA | F3: Notes
A4: STEEL BEAMS - Per S2/S7 (BY STEEL CONTRACTOR)
A5: W6x40 beam - Living area | B5: W6x40 | C5: 4 | D5: EA | E5: =C5*24 -> 96 | F5: ~24' spans, verify w/ steel
A6: W8x31 beam - Entry/Kitchen | B6: W8x31 | C6: 3 | D6: EA | E6: =C6*20 -> 60 | F6: ~20' spans
A7: W10x33 beam - Long spans | B7: W10x33 | C7: 2 | D7: EA | E7: =C7*28 -> 56 | F7: ~28' spans
A8: HSS 6x6x3/8 columns | B8: HSS6x6 | C8: 12 | D8: EA | E8: =C8*12 -> 144 | F8: ~12' heights
A9: 3/8" base plates (typ) | B9: 12x12x3/8 | C9: 12 | D9: EA | E9: =C9 -> 12 | F9: Per S7 detail
A10: ¾" anchor bolts for columns | B10: ¾x12 AB | C10: 48 | D10: EA | E10: =C10 -> 48 | F10: 4 per column
A12: NOTE: Steel quantities shown for reference only. Verify with structural engineer and steel fabricator.
